<?xml version="1.0" encoding="utf-8"?>
<!-- This URDF was automatically created by SolidWorks to URDF Exporter! Originally created by Stephen Brawner (brawner@gmail.com) 
     Commit Version: 1.5.1-0-g916b5db  Build Version: 1.5.7152.31018
     For more information, please see http://wiki.ros.org/sw_urdf_exporter -->
<robot
  name="fanuc_arcmate120ibe">
  <link
    name="base_link">
    <inertial>
      <origin
        xyz="-2.4955E-16 0.14736 -1.0254E-16"
        rpy="0 0 0" />
      <mass
        value="31.134" />
      <inertia
        ixx="0.49942"
        ixy="-1.0616E-15"
        ixz="-9.0209E-17"
        iyy="0.51858"
        iyz="-4.0477E-16"
        izz="0.49942" />
    </inertial>
    <visual>
      <origin
        xyz="0 0 0"
        rpy="0 0 0" />
      <geometry>
        <mesh
          filename="package://fanuc_arcmate120ibe_support/meshes/base_link.STL" />
      </geometry>
      <material
        name="">
        <color
          rgba="1 1 0 1" />
      </material>
    </visual>
    <collision>
      <origin
        xyz="0 0 0"
        rpy="0 0 0" />
      <geometry>
        <mesh
          filename="package://fanuc_arcmate120ibe_support/meshes/base_link.STL" />
      </geometry>
    </collision>
  </link>
  <link
    name="link_1">
    <inertial>
      <origin
        xyz="-0.0053665 0.12231 0.048066"
        rpy="0 0 0" />
      <mass
        value="7.7668" />
      <inertia
        ixx="0.14019"
        ixy="-0.00027046"
        ixz="-0.013883"
        iyy="0.11582"
        iyz="-0.035159"
        izz="0.098746" />
    </inertial>
    <visual>
      <origin
        xyz="0 0 0"
        rpy="0 0 0" />
      <geometry>
        <mesh
          filename="package://fanuc_arcmate120ibe_support/meshes/link_1.STL" />
      </geometry>
      <material
        name="">
        <color
          rgba="1 1 0 1" />
      </material>
    </visual>
    <collision>
      <origin
        xyz="0 0 0"
        rpy="0 0 0" />
      <geometry>
        <mesh
          filename="package://fanuc_arcmate120ibe_support/meshes/link_1.STL" />
      </geometry>
    </collision>
  </link>
  <joint
    name="joint_1"
    type="revolute">
    <origin
      xyz="0 0 0.3"
      rpy="1.5708 0 1.5708" />
    <parent
      link="base_link" />
    <child
      link="link_1" />
    <axis
      xyz="0 1 0" />
    <limit
      lower="-2.96"
      upper="2.96"
      effort="0"
      velocity="2.879" />
  </joint>
  <link
    name="link_2">
    <inertial>
      <origin
        xyz="-3.8025E-15 0.34293 -0.025926"
        rpy="0 0 0" />
      <mass
        value="5.7228" />
      <inertia
        ixx="0.50203"
        ixy="-2.184E-18"
        ixz="-1.3063E-19"
        iyy="0.011719"
        iyz="0.00031913"
        izz="0.5118" />
    </inertial>
    <visual>
      <origin
        xyz="0 0 0.05"
        rpy="0 0 0" />
      <geometry>
        <mesh
          filename="package://fanuc_arcmate120ibe_support/meshes/link_2.STL" />
      </geometry>
      <material
        name="">
        <color
          rgba="1 1 0 1" />
      </material>
    </visual>
    <collision>
      <origin
        xyz="0 0 0.05"
        rpy="0 0 0" />
      <geometry>
        <mesh
          filename="package://fanuc_arcmate120ibe_support/meshes/link_2.STL" />
      </geometry>
    </collision>
  </link>
  <joint
    name="joint_2"
    type="revolute">
    <origin
      xyz="0.08 0.225 0.15"
      rpy="0 1.5708 0" />
    <parent
      link="link_1" />
    <child
      link="link_2" />
    <axis
      xyz="0 0 1" />
    <limit
      lower="-1.57"
      upper="2.79"
      effort="0"
      velocity="2.879" />
  </joint>
  <link
    name="link_3">
    <inertial>
      <origin
        xyz="-0.10187 0.057917 -0.098456"
        rpy="0 0 0" />
      <mass
        value="6.2061" />
      <inertia
        ixx="0.060263"
        ixy="0.0072606"
        ixz="-0.0048645"
        iyy="0.057072"
        iyz="0.009519"
        izz="0.053965" />
    </inertial>
    <visual>
      <origin
        xyz="0 0 0"
        rpy="0 3.14 0" />
      <geometry>
        <mesh
          filename="package://fanuc_arcmate120ibe_support/meshes/link_3.STL" />
      </geometry>
      <material
        name="">
        <color
          rgba="1 1 0 1" />
      </material>
    </visual>
    <collision>
      <origin
        xyz="0 0 0"
        rpy="0 3.14 0" />
      <geometry>
        <mesh
          filename="package://fanuc_arcmate120ibe_support/meshes/link_3.STL" />
      </geometry>
    </collision>
  </link>
  <joint
    name="joint_3"
    type="revolute">
    <origin
      xyz="0 0.77 0"
      rpy="3.1416 0 3.1416" />
    <parent
      link="link_2" />
    <child
      link="link_3" />
    <axis
      xyz="0 0 1" />
    <limit
      lower="-4.014"
      upper="4.014"
      effort="0"
      velocity="3.054" />
  </joint>
  <link
    name="link_4">
    <inertial>
      <origin
        xyz="0.0063245 0.00018455 -0.29849"
        rpy="0 0 0" />
      <mass
        value="6.3034" />
      <inertia
        ixx="0.14928"
        ixy="1.1782E-05"
        ixz="0.0072059"
        iyy="0.15365"
        iyz="-3.6214E-05"
        izz="0.016928" />
    </inertial>
    <visual>
      <origin
        xyz="0 0 0"
        rpy="3.14 0 3.14" />
      <geometry>
        <mesh
          filename="package://fanuc_arcmate120ibe_support/meshes/link_4.STL" />
      </geometry>
      <material
        name="">
        <color
          rgba="1 1 0 1" />
      </material>
    </visual>
    <collision>
      <origin
        xyz="0 0 0"
        rpy="3.14 0 3.14" />
      <geometry>
        <mesh
          filename="package://fanuc_arcmate120ibe_support/meshes/link_4.STL" />
      </geometry>
    </collision>
  </link>
  <joint
    name="joint_4"
    type="revolute">
    <origin
      xyz="0.2 0.1 0.08"
      rpy="0 1.5708 0" />
    <parent
      link="link_3" />
    <child
      link="link_4" />
    <axis
      xyz="0 0 -1" />
    <limit
      lower="-3.49"
      upper="3.49"
      effort="0"
      velocity="6.108" />
  </joint>
  <link
    name="link_5">
    <inertial>
      <origin
        xyz="-0.014948 0 -0.00014938"
        rpy="0 0 0" />
      <mass
        value="1.4974" />
      <inertia
        ixx="0.0022102"
        ixy="-3.9883E-19"
        ixz="3.3435E-06"
        iyy="0.00454"
        iyz="9.1308E-20"
        izz="0.0047819" />
    </inertial>
    <visual>
      <origin
        xyz="0 0 0"
        rpy="0 0 0" />
      <geometry>
        <mesh
          filename="package://fanuc_arcmate120ibe_support/meshes/link_5.STL" />
      </geometry>
      <material
        name="">
        <color
          rgba="1 1 0 1" />
      </material>
    </visual>
    <collision>
      <origin
        xyz="0 0 0"
        rpy="0 0 0" />
      <geometry>
        <mesh
          filename="package://fanuc_arcmate120ibe_support/meshes/link_5.STL" />
      </geometry>
    </collision>
  </link>
  <joint
    name="joint_5"
    type="revolute">
    <origin
      xyz="0 0 0.54"
      rpy="0 -1.5708 0" />
    <parent
      link="link_4" />
    <child
      link="link_5" />
    <axis
      xyz="0 0 1" />
    <limit
      lower="-2"
      upper="2"
      effort="0"
      velocity="5.934" />
  </joint>
  <link
    name="link_6">
    <inertial>
      <origin
        xyz="5.8828E-14 -3.217E-05 0.013288"
        rpy="0 0 0" />
      <mass
        value="0.1648" />
      <inertia
        ixx="9.0491E-05"
        ixy="-4.3139E-22"
        ixz="-7.3264E-19"
        iyy="9.0591E-05"
        iyz="6.739E-08"
        izz="0.00016145" />
    </inertial>
    <visual>
      <origin
        xyz="0 0 -0.03"
        rpy="0 0 0" />
      <geometry>
        <mesh
          filename="package://fanuc_arcmate120ibe_support/meshes/link_6.STL" />
      </geometry>
      <material
        name="">
        <color
          rgba="1 1 0 1" />
      </material>
    </visual>
    <collision>
      <origin
        xyz="0 0 -0.03"
        rpy="0 0 0" />
      <geometry>
        <mesh
          filename="package://fanuc_arcmate120ibe_support/meshes/link_6.STL" />
      </geometry>
    </collision>
  </link>
  <joint
    name="joint_6"
    type="revolute">
    <origin
      xyz="0.1 0 0"
      rpy="0 -1.57 3.14" />
    <parent
      link="link_5" />
    <child
      link="link_6" />
    <axis
      xyz="0 0 1" />
    <limit
      lower="-7.853"
      upper="7.853"
      effort="0"
      velocity="9.075" />
  </joint>

  <!--GAZEBO CONFIGURATION-->

  <gazebo>
        <plugin name="gazebo_ros_control" filename="libgazebo_ros_control.so">
            <robotNamespace>/fanuc120ibe</robotNamespace>
        </plugin>
  </gazebo>

  <!-- To fix the "base_link" with Gazebo's "world" reference frame -->
  <link 
    name="world" />
  <joint name="fixed" type="fixed">
    <parent 
      link="world" />
    <child 
      link="base_link" />
    </joint>

    <!-- Gazebo Joint properties-->
    <gazebo reference="base_link">
        <selfCollide>true</selfCollide>
        <gravity>false</gravity>
    </gazebo>
    <gazebo reference="link_1">
        <selfCollide>true</selfCollide>
        <gravity>false</gravity>
    </gazebo>
    <gazebo reference="link_2">
        <selfCollide>true</selfCollide>
        <gravity>false</gravity>
    </gazebo>
    <gazebo reference="link_3">
        <selfCollide>true</selfCollide>
        <gravity>false</gravity>
    </gazebo>
    <gazebo reference="link_4">
        <selfCollide>true</selfCollide>
        <gravity>false</gravity>
    </gazebo>
    <gazebo reference="link_5">
        <selfCollide>true</selfCollide>
        <gravity>false</gravity>
    </gazebo>
    <gazebo reference="link_6">
        <selfCollide>true</selfCollide>
        <gravity>false</gravity>
    </gazebo>

    <!-- Definifn the typoe of transmission between the actuators and joints-->
    <!-- Also the type of hardware interface we use when we interface with the ROS controllers-->
    <transmission name="trans_joint_1">
        <type>transmission_interface/SimpleTransmission</type>
        <joint name="joint_1">
            <hardwareInterface>hardware_interface/PositionJointInterface</hardwareInterface>
        </joint>
        <actuator name="joint_1_motor">
            <hardwareInterface>hardware_interface/PositionJointInterface</hardwareInterface>
            <mechanicalReduction>1</mechanicalReduction>
        </actuator>
    </transmission>
    <transmission name="trans_joint_2">
        <type>transmission_interface/SimpleTransmission</type>
        <joint name="joint_2">
            <hardwareInterface>hardware_interface/PositionJointInterface</hardwareInterface>
        </joint>
        <actuator name="joint_2_motor">
            <hardwareInterface>hardware_interface/PositionJointInterface</hardwareInterface>
            <mechanicalReduction>1</mechanicalReduction>
        </actuator>
    </transmission>
    <transmission name="trans_joint_3">
        <type>transmission_interface/SimpleTransmission</type>
        <joint name="joint_3">
            <hardwareInterface>hardware_interface/PositionJointInterface</hardwareInterface>
        </joint>
        <actuator name="joint_3_motor">
            <hardwareInterface>hardware_interface/PositionJointInterface</hardwareInterface>
            <mechanicalReduction>1</mechanicalReduction>
        </actuator>
    </transmission>
    <transmission name="trans_joint_4">
        <type>transmission_interface/SimpleTransmission</type>
        <joint name="joint_4">
            <hardwareInterface>hardware_interface/PositionJointInterface</hardwareInterface>
        </joint>
        <actuator name="joint_4_motor">
            <hardwareInterface>hardware_interface/PositionJointInterface</hardwareInterface>
            <mechanicalReduction>1</mechanicalReduction>
        </actuator>
    </transmission>
    <transmission name="trans_joint_5">
        <type>transmission_interface/SimpleTransmission</type>
        <joint name="joint_5">
            <hardwareInterface>hardware_interface/PositionJointInterface</hardwareInterface>
        </joint>
        <actuator name="joint_5_motor">
            <hardwareInterface>hardware_interface/PositionJointInterface</hardwareInterface>
            <mechanicalReduction>1</mechanicalReduction>
        </actuator>
    </transmission>
    <transmission name="trans_joint_6">
        <type>transmission_interface/SimpleTransmission</type>
        <joint name="joint_6">
            <hardwareInterface>hardware_interface/PositionJointInterface</hardwareInterface>
        </joint>
        <actuator name="joint_6_motor">
            <hardwareInterface>hardware_interface/PositionJointInterface</hardwareInterface>
            <mechanicalReduction>1</mechanicalReduction>
        </actuator>
    </transmission>

    
    
</robot>